<?xml version="1.0"?>
<!--
  Differential-drive sweeping robot URDF model.

  Geometry:
    - Circular body:  radius 0.175 m, height 0.10 m
    - Two drive wheels (left / right)
    - One front caster
    - LiDAR sensor (Hokuyo UTM-30LX style)
    - IMU sensor

  Coordinate frames:
    base_footprint → base_link → [left_wheel, right_wheel, caster, lidar, imu]
-->
<robot name="sweeper_robot"
       xmlns:xacro="http://www.ros.org/wiki/xacro">

  <!-- ================================================================ -->
  <!-- Material definitions                                               -->
  <!-- ================================================================ -->
  <material name="dark_grey">
    <color rgba="0.2 0.2 0.2 1.0"/>
  </material>
  <material name="light_grey">
    <color rgba="0.7 0.7 0.7 1.0"/>
  </material>
  <material name="blue">
    <color rgba="0.1 0.4 0.8 1.0"/>
  </material>
  <material name="black">
    <color rgba="0.0 0.0 0.0 1.0"/>
  </material>
  <material name="white">
    <color rgba="1.0 1.0 1.0 1.0"/>
  </material>

  <!-- ================================================================ -->
  <!-- Links                                                              -->
  <!-- ================================================================ -->

  <!-- base_footprint: zero-height reference frame on the ground -->
  <link name="base_footprint"/>

  <!-- base_link: geometric centre of the robot body -->
  <link name="base_link">
    <inertial>
      <mass value="3.5"/>
      <origin xyz="0 0 0"/>
      <inertia ixx="0.0564" ixy="0" ixz="0"
               iyy="0.0564" iyz="0"
               izz="0.1122"/>
    </inertial>
    <visual>
      <geometry>
        <cylinder radius="0.175" length="0.10"/>
      </geometry>
      <material name="dark_grey"/>
    </visual>
    <collision>
      <geometry>
        <cylinder radius="0.175" length="0.10"/>
      </geometry>
    </collision>
  </link>

  <!-- Left drive wheel -->
  <link name="left_wheel">
    <inertial>
      <mass value="0.5"/>
      <origin xyz="0 0 0"/>
      <inertia ixx="0.001" ixy="0" ixz="0"
               iyy="0.001" iyz="0"
               izz="0.002"/>
    </inertial>
    <visual>
      <geometry><cylinder radius="0.05" length="0.04"/></geometry>
      <material name="black"/>
    </visual>
    <collision>
      <geometry><cylinder radius="0.05" length="0.04"/></geometry>
    </collision>
  </link>

  <!-- Right drive wheel -->
  <link name="right_wheel">
    <inertial>
      <mass value="0.5"/>
      <origin xyz="0 0 0"/>
      <inertia ixx="0.001" ixy="0" ixz="0"
               iyy="0.001" iyz="0"
               izz="0.002"/>
    </inertial>
    <visual>
      <geometry><cylinder radius="0.05" length="0.04"/></geometry>
      <material name="black"/>
    </visual>
    <collision>
      <geometry><cylinder radius="0.05" length="0.04"/></geometry>
    </collision>
  </link>

  <!-- Front caster wheel (passive) -->
  <link name="caster_wheel">
    <inertial>
      <mass value="0.1"/>
      <origin xyz="0 0 0"/>
      <inertia ixx="0.0001" ixy="0" ixz="0"
               iyy="0.0001" iyz="0"
               izz="0.0001"/>
    </inertial>
    <visual>
      <geometry><sphere radius="0.025"/></geometry>
      <material name="light_grey"/>
    </visual>
    <collision>
      <geometry><sphere radius="0.025"/></geometry>
    </collision>
  </link>

  <!-- LiDAR sensor link -->
  <link name="lidar_link">
    <inertial>
      <mass value="0.15"/>
      <origin xyz="0 0 0"/>
      <inertia ixx="0.0001" ixy="0" ixz="0"
               iyy="0.0001" iyz="0"
               izz="0.0001"/>
    </inertial>
    <visual>
      <geometry><cylinder radius="0.035" length="0.05"/></geometry>
      <material name="blue"/>
    </visual>
    <collision>
      <geometry><cylinder radius="0.035" length="0.05"/></geometry>
    </collision>
  </link>

  <!-- IMU link -->
  <link name="imu_link">
    <inertial>
      <mass value="0.01"/>
      <origin xyz="0 0 0"/>
      <inertia ixx="1e-6" ixy="0" ixz="0"
               iyy="1e-6" iyz="0"
               izz="1e-6"/>
    </inertial>
    <visual>
      <geometry><box size="0.03 0.03 0.01"/></geometry>
      <material name="white"/>
    </visual>
  </link>

  <!-- ================================================================ -->
  <!-- Joints                                                             -->
  <!-- ================================================================ -->

  <joint name="base_footprint_joint" type="fixed">
    <parent link="base_footprint"/>
    <child  link="base_link"/>
    <origin xyz="0 0 0.05" rpy="0 0 0"/>
  </joint>

  <joint name="left_wheel_joint" type="continuous">
    <parent link="base_link"/>
    <child  link="left_wheel"/>
    <origin xyz="0.0 0.15 -0.025" rpy="-1.5708 0 0"/>
    <axis   xyz="0 0 1"/>
  </joint>

  <joint name="right_wheel_joint" type="continuous">
    <parent link="base_link"/>
    <child  link="right_wheel"/>
    <origin xyz="0.0 -0.15 -0.025" rpy="-1.5708 0 0"/>
    <axis   xyz="0 0 1"/>
  </joint>

  <joint name="caster_joint" type="fixed">
    <parent link="base_link"/>
    <child  link="caster_wheel"/>
    <origin xyz="0.13 0.0 -0.045" rpy="0 0 0"/>
  </joint>

  <joint name="lidar_joint" type="fixed">
    <parent link="base_link"/>
    <child  link="lidar_link"/>
    <origin xyz="0.0 0.0 0.085" rpy="0 0 0"/>
  </joint>

  <joint name="imu_joint" type="fixed">
    <parent link="base_link"/>
    <child  link="imu_link"/>
    <origin xyz="0.0 0.0 0.05" rpy="0 0 0"/>
  </joint>

  <!-- ================================================================ -->
  <!-- Gazebo plugins                                                     -->
  <!-- ================================================================ -->

  <!-- Differential drive controller -->
  <gazebo>
    <plugin name="differential_drive_controller"
            filename="libgazebo_ros_diff_drive.so">
      <update_rate>50</update_rate>
      <left_joint>left_wheel_joint</left_joint>
      <right_joint>right_wheel_joint</right_joint>
      <wheel_separation>0.30</wheel_separation>
      <wheel_diameter>0.10</wheel_diameter>
      <max_wheel_torque>20</max_wheel_torque>
      <max_wheel_acceleration>1.0</max_wheel_acceleration>
      <command_topic>cmd_vel</command_topic>
      <odometry_topic>odom</odometry_topic>
      <odometry_frame>odom</odometry_frame>
      <robot_base_frame>base_link</robot_base_frame>
      <publish_odom>true</publish_odom>
      <publish_odom_tf>true</publish_odom_tf>
      <publish_wheel_tf>false</publish_wheel_tf>
    </plugin>
  </gazebo>

  <!-- 2-D LiDAR (Hokuyo-style) -->
  <gazebo reference="lidar_link">
    <sensor name="lidar" type="ray">
      <always_on>true</always_on>
      <visualize>true</visualize>
      <update_rate>10</update_rate>
      <ray>
        <scan>
          <horizontal>
            <samples>360</samples>
            <resolution>1</resolution>
            <min_angle>-3.14159</min_angle>
            <max_angle>3.14159</max_angle>
          </horizontal>
        </scan>
        <range>
          <min>0.10</min>
          <max>10.0</max>
          <resolution>0.01</resolution>
        </range>
        <noise>
          <type>gaussian</type>
          <mean>0.0</mean>
          <stddev>0.01</stddev>
        </noise>
      </ray>
      <plugin name="gazebo_ros_lidar_controller"
              filename="libgazebo_ros_ray_sensor.so">
        <ros>
          <remapping>~/out:=scan</remapping>
        </ros>
        <output_type>sensor_msgs/LaserScan</output_type>
        <frame_name>lidar_link</frame_name>
      </plugin>
    </sensor>
  </gazebo>

  <!-- IMU sensor -->
  <gazebo reference="imu_link">
    <sensor name="imu" type="imu">
      <always_on>true</always_on>
      <update_rate>100</update_rate>
      <imu>
        <angular_velocity>
          <x><noise type="gaussian"><mean>0</mean><stddev>0.002</stddev></noise></x>
          <y><noise type="gaussian"><mean>0</mean><stddev>0.002</stddev></noise></y>
          <z><noise type="gaussian"><mean>0</mean><stddev>0.002</stddev></noise></z>
        </angular_velocity>
        <linear_acceleration>
          <x><noise type="gaussian"><mean>0</mean><stddev>0.017</stddev></noise></x>
          <y><noise type="gaussian"><mean>0</mean><stddev>0.017</stddev></noise></y>
          <z><noise type="gaussian"><mean>0</mean><stddev>0.017</stddev></noise></z>
        </linear_acceleration>
      </imu>
      <plugin name="gazebo_ros_imu_controller"
              filename="libgazebo_ros_imu_sensor.so">
        <ros>
          <remapping>~/out:=imu</remapping>
        </ros>
        <initial_orientation_as_reference>false</initial_orientation_as_reference>
      </plugin>
    </sensor>
  </gazebo>

</robot>
